Workbook
Name ExternalData_8: '3 customers'!$A$1:$J$92

Sheet 1 orders
A1: orderID | B1: customerID | C1: orderDate | D1: requiredDate | E1: shippedDate | F1: arrivedDate | G1: productID | H1: orderPrice | I1: orderQuantity | J1: discountApllied | K1: freightCost | L1: shipVia
A2: 10248 | B2: VINET | C2: 44746 | D2: 44774 | E2: 44758 | F2: 44766 | G2: 11 | H2: 14 | I2: 12 | J2: 0 | K2: 32.38 | L2: Federal Shipping
A3: 10248 | B3: VINET | C3: 44746 | D3: 44774 | E3: 44758 | F3: 44766 | G3: 42 | H3: 9.8 | I3: 10 | J3: 0 | K3: 32.38 | L3: Federal Shipping
A4: 10248 | B4: VINET | C4: 44746 | D4: 44774 | E4: 44758 | F4: 44766 | G4: 72 | H4: 34.8 | I4: 5 | J4: 0 | K4: 32.38 | L4: Federal Shipping
A5: 10249 | B5: TOMSP | C5: 44747 | D5: 44789 | E5: 44752 | F5: 44756 | G5: 14 | H5: 18.6 | I5: 9 | J5: 0 | K5: 11.61 | L5: Speedy Express
A6: 10249 | B6: TOMSP | C6: 44747 | D6: 44789 | E6: 44752 | F6: 44756 | G6: 51 | H6: 42.4 | I6: 40 | J6: 0 | K6: 11.61 | L6: Speedy Express
A7: 10250 | B7: HANAR | C7: 44750 | D7: 44778 | E7: 44754 | F7: 44771 | G7: 41 | H7: 7.7 | I7: 10 | J7: 0 | K7: 65.83 | L7: United Package
A8: 10250 | B8: HANAR | C8: 44750 | D8: 44778 | E8: 44754 | F8: 44771 | G8: 51 | H8: 42.4 | I8: 35 | J8: 0.15 | K8: 65.83 | L8: United Package
A9: 10250 | B9: HANAR | C9: 44750 | D9: 44778 | E9: 44754 | F9: 44771 | G9: 65 | H9: 16.8 | I9: 15 | J9: 0.15 | K9: 65.83 | L9: United Package
A10: 10251 | B10: VICTE | C10: 44750 | D10: 44778 | E10: 44757 | F10: 44761 | G10: 22 | H10: 16.8 | I10: 6 | J10: 0.05 | K10: 41.34 | L10: Speedy Express
A11: 10251 | B11: VICTE | C11: 44750 | D11: 44778 | E11: 44757 | F11: 44761 | G11: 57 | H11: 15.6 | I11: 15 | J11: 0.05 | K11: 41.34 | L11: Speedy Express
A12: 10251 | B12: VICTE | C12: 44750 | D12: 44778 | E12: 44757 | F12: 44761 | G12: 65 | H12: 16.8 | I12: 20 | J12: 0 | K12: 41.34 | L12: Speedy Express
A13: 10252 | B13: SUPRD | C13: 44751 | D13: 44779 | E13: 44753 | F13: 44766 | G13: 20 | H13: 64.8 | I13: 40 | J13: 0.05 | K13: 51.3 | L13: United Package
... A1964: 11007 | B1964: PRINI | C1964: 45390 | D1964: 45418 | E1964: 45395 | F1964: 45407 | G1964: 42 | H1964: 14 | I1964: 14 | J1964: 0 | K1964: 202.24 | L1964: United Package
A1965: 11008 | B1965: ERNSH | C1965: 45390 | D1965: 45418 | G1965: 28 | H1965: 45.6 | I1965: 70 | J1965: 0.05 | K1965: 79.46 | L1965: Federal Shipping
A1966: 11008 | B1966: ERNSH | C1966: 45390 | D1966: 45418 | G1966: 34 | H1966: 14 | I1966: 90 | J1966: 0.05 | K1966: 79.46 | L1966: Federal Shipping
A1967: 11008 | B1967: ERNSH | C1967: 45390 | D1967: 45418 | G1967: 71 | H1967: 21.5 | I1967: 21 | J1967: 0 | K1967: 79.46 | L1967: Federal Shipping
A1968: 11009 | B1968: GODOS | C1968: 45390 | D1968: 45418 | E1968: 45392 | F1968: 45400 | G1968: 24 | H1968: 4.5 | I1968: 12 | J1968: 0 | K1968: 59.11 | L1968: Speedy Express
A1969: 11009 | B1969: GODOS | C1969: 45390 | D1969: 45418 | E1969: 45392 | F1969: 45400 | G1969: 36 | H1969: 19 | I1969: 18 | J1969: 0.25 | K1969: 59.11 | L1969: Speedy Express
A1970: 11009 | B1970: GODOS | C1970: 45390 | D1970: 45418 | E1970: 45392 | F1970: 45400 | G1970: 60 | H1970: 34 | I1970: 9 | J1970: 0 | K1970: 59.11 | L1970: Speedy Express
A1971: 11010 | B1971: REGGC | C1971: 45391 | D1971: 45419 | E1971: 45403 | F1971: 45414 | G1971: 7 | H1971: 30 | I1971: 20 | J1971: 0 | K1971: 28.71 | L1971: United Package
A1972: 11010 | B1972: REGGC | C1972: 45391 | D1972: 45419 | E1972: 45403 | F1972: 45414 | G1972: 24 | H1972: 4.5 | I1972: 10 | J1972: 0 | K1972: 28.71 | L1972: United Package
A1973: 11011 | B1973: ALFKI | C1973: 45391 | D1973: 45419 | E1973: 45395 | F1973: 45398 | G1973: 58 | H1973: 13.25 | I1973: 40 | J1973: 0.05 | K1973: 1.21 | L1973: Speedy Express
A1974: 11011 | B1974: ALFKI | C1974: 45391 | D1974: 45419 | E1974: 45395 | F1974: 45398 | G1974: 71 | H1974: 21.5 | I1974: 20 | J1974: 0 | K1974: 1.21 | L1974: Speedy Express
A1975: 11012 | B1975: FRANK | C1975: 45391 | D1975: 45405 | E1975: 45399 | F1975: 45406 | G1975: 19 | H1975: 9.2 | I1975: 50 | J1975: 0.05 | K1975: 242.95 | L1975: Federal Shipping
A1976: 11012 | B1976: FRANK | C1976: 45391 | D1976: 45405 | E1976: 45399 | F1976: 45406 | G1976: 60 | H1976: 34 | I1976: 36 | J1976: 0.05 | K1976: 242.95 | L1976: Federal Shipping
A1977: 11012 | B1977: FRANK | C1977: 45391 | D1977: 45405 | E1977: 45399 | F1977: 45406 | G1977: 71 | H1977: 21.5 | I1977: 60 | J1977: 0.05 | K1977: 242.95 | L1977: Federal Shipping
A1978: 11013 | B1978: ROMEY | C1978: 45391 | D1978: 45419 | E1978: 45392 | F1978: 45400 | G1978: 23 | H1978: 9 | I1978: 10 | J1978: 0 | K1978: 32.99 | L1978: Speedy Express
A1979: 11013 | B1979: ROMEY | C1979: 45391 | D1979: 45419 | E1979: 45392 | F1979: 45400 | G1979: 42 | H1979: 14 | I1979: 4 | J1979: 0 | K1979: 32.99 | L1979: Speedy Express
... A1992: 11018 | B1992: LONEP | C1992: 45395 | D1992: 45423 | E1992: 45398 | F1992: 45417 | G1992: 56 | H1992: 38 | I1992: 5 | J1992: 0 | K1992: 11.65 | L1992: United Package
A1993: 11019 | B1993: RANCH | C1993: 45395 | D1993: 45423 | G1993: 46 | H1993: 12 | I1993: 3 | J1993: 0 | K1993: 3.17 | L1993: Federal Shipping
A1994: 11019 | B1994: RANCH | C1994: 45395 | D1994: 45423 | G1994: 49 | H1994: 20 | I1994: 2 | J1994: 0 | K1994: 3.17 | L1994: Federal Shipping
A1995: 11020 | B1995: OTTIK | C1995: 45396 | D1995: 45424 | E1995: 45398 | F1995: 45407 | G1995: 10 | H1995: 31 | I1995: 24 | J1995: 0.15 | K1995: 43.3 | L1995: United Package
A1996: 11021 | B1996: QUICK | C1996: 45396 | D1996: 45424 | E1996: 45403 | F1996: 45405 | G1996: 2 | H1996: 19 | I1996: 11 | J1996: 0.25 | K1996: 297.18 | L1996: Speedy Express
A1997: 11021 | B1997: QUICK | C1997: 45396 | D1997: 45424 | E1997: 45403 | F1997: 45405 | G1997: 20 | H1997: 81 | I1997: 15 | J1997: 0 | K1997: 297.18 | L1997: Speedy Express
A1998: 11021 | B1998: QUICK | C1998: 45396 | D1998: 45424 | E1998: 45403 | F1998: 45405 | G1998: 26 | H1998: 31.23 | I1998: 63 | J1998: 0 | K1998: 297.18 | L1998: Speedy Express
A1999: 11021 | B1999: QUICK | C1999: 45396 | D1999: 45424 | E1999: 45403 | F1999: 45405 | G1999: 51 | H1999: 53 | I1999: 44 | J1999: 0.25 | K1999: 297.18 | L1999: Speedy Express
A2000: 11021 | B2000: QUICK | C2000: 45396 | D2000: 45424 | E2000: 45403 | F2000: 45405 | G2000: 72 | H2000: 34.8 | I2000: 35 | J2000: 0 | K2000: 297.18 | L2000: Speedy Express
A2001: 11022 | B2001: HANAR | C2001: 45396 | D2001: 45424 | E2001: 45416 | F2001: 45437 | G2001: 19 | H2001: 9.2 | I2001: 35 | J2001: 0 | K2001: 6.27 | L2001: United Package
A2002: 11022 | B2002: HANAR | C2002: 45396 | D2002: 45424 | E2002: 45416 | F2002: 45437 | G2002: 69 | H2002: 36 | I2002: 30 | J2002: 0 | K2002: 6.27 | L2002: United Package
...

Sheet 2 products
A1: productID | B1: productName | C1: quantityPerUnit | D1: unitsInStock | E1: unitsOnOrder | F1: reorderLevel | G1: discontinued | H1: purchasePrice_2022 | I1: purchasePrice_2023 | J1: purchasePrice_2024 | K1: productRating | L1: categoryName | M1: categoryDescription | N1: supplierName | O1: supplierCity | P1: supplierCountry
A2: 1 | B2: Chai | C2: 10 boxes x 20 bags | D2: 39 | E2: 0 | F2: 10 | G2: 0 | H2: 9.5742072 | I2: 12.158476 | J2: 12.177575 | K2: 4.5 | L2: Beverages | M2: Soft drinks coffees teas beers and ales | N2: Exotic Liquids | O2: London | P2: UK
A3: 2 | B3: Chang | C3: 24 - 12 oz bottles | D3: 17 | E3: 40 | F3: 25 | G3: 0 | H3: 9.7687469 | I3: 12.146269 | J3: 11.938437 | K3: 4.5 | L3: Beverages | M3: Soft drinks coffees teas beers and ales | N3: Exotic Liquids | O3: London | P3: UK
A4: 3 | B4: Aniseed Syrup | C4: 12 - 550 ml bottles | D4: 13 | E4: 70 | F4: 25 | G4: 0 | H4: 5.6218196 | I4: 6.3998026 | J4: 7.2059177 | K4: 5 | L4: Condiments | M4: Sweet and savory sauces relishes spreads and seasonings | N4: Exotic Liquids | O4: London | P4: UK
A5: 4 | B5: Chef Anton's Cajun Seasoning | C5: 48 - 6 oz jars | D5: 53 | E5: 0 | F5: 0 | G5: 0 | H5: 12.120073 | I5: 13.810471 | J5: 14.372802 | K5: 5 | L5: Condiments | M5: Sweet and savory sauces relishes spreads and seasonings | N5: New Orleans Cajun Delights | O5: New Orleans | P5: USA
A6: 5 | B6: Chef Anton's Gumbo Mix | C6: 36 boxes | D6: 0 | E6: 0 | F6: 0 | G6: 1 | H6: 10.905906 | I6: 14.652583 | J6: 13.963374 | K6: 4.5 | L6: Condiments | M6: Sweet and savory sauces relishes spreads and seasonings | N6: New Orleans Cajun Delights | O6: New Orleans | P6: USA
A7: 6 | B7: Grandma's Boysenberry Spread | C7: 12 - 8 oz jars | D7: 120 | E7: 0 | F7: 25 | G7: 0 | H7: 13.640303 | I7: 17.851104 | J7: 17.241659 | K7: 5 | L7: Condiments | M7: Sweet and savory sauces relishes spreads and seasonings | N7: Grandma Kelly's Homestead | O7: Ann Arbor | P7: USA
A8: 8 | B8: Northwoods Cranberry Sauce | C8: 12 - 12 oz jars | D8: 6 | E8: 0 | F8: 0 | G8: 0 | H8: 19.171769 | I8: 26.106205 | J8: 27.417709 | K8: 5 | L8: Condiments | M8: Sweet and savory sauces relishes spreads and seasonings | N8: Grandma Kelly's Homestead | O8: Ann Arbor | P8: USA
A9: 9 | B9: Mishi Kobe Niku | C9: 18 - 500 g pkgs. | D9: 29 | E9: 0 | F9: 0 | G9: 1 | I9: 59.95981 | J9: 72.668633 | K9: 4 | L9: Meat/Poultry | M9: Prepared meats | N9: Tokyo Traders | O9: Tokyo | P9: Japan
A10: 7 | B10: Uncle Bob's Organic Dried Pears | C10: 12 - 1 lb pkgs. | D10: 15 | E10: 0 | F10: 10 | G10: 0 | H10: 16.429974 | I10: 21.392446 | J10: 23.522222 | K10: 4.5 | L10: Produce | M10: Dried fruit and bean curd | N10: Grandma Kelly's Homestead | O10: Ann Arbor | P10: USA
A11: 10 | B11: Ikura | C11: 12 - 200 ml jars | D11: 31 | E11: 0 | F11: 0 | G11: 0 | H11: 16.076307 | I11: 20.727219 | J11: 20.903946 | K11: 3.5 | L11: Seafood | M11: Seaweed and fish | N11: Tokyo Traders | O11: Tokyo | P11: Japan
A12: 11 | B12: Queso Cabrales | C12: 1 kg pkg. | D12: 22 | E12: 30 | F12: 30 | G12: 0 | H12: 10.582311 | I12: 12.901881 | J12: 13.868363 | K12: 5 | L12: Dairy Products | M12: Cheeses | N12: Cooperativa de Quesos 'Las Cabras' | O12: Oviedo | P12: Spain
A13: 12 | B13: Queso Manchego La Pastora | C13: 10 - 500 g pkgs. | D13: 86 | E13: 0 | F13: 0 | G13: 0 | H13: 20.012451 | I13: 23.792166 | J13: 25.02511 | K13: 5 | L13: Dairy Products | M13: Cheeses | N13: Cooperativa de Quesos 'Las Cabras' | O13: Oviedo | P13: Spain
A14: 13 | B14: Konbu | C14: 2 kg box | D14: 24 | E14: 0 | F14: 5 | G14: 0 | H14: 3.2367274 | I14: 3.8657749 | J14: 3.966387 | K14: 4 | L14: Seafood | M14: Seaweed and fish | N14: Mayumi's | O14: Osaka | P14: Japan
A15: 14 | B15: Tofu | C15: 40 - 100 g pkgs. | D15: 35 | E15: 0 | F15: 0 | G15: 0 | H15: 13.952541 | I15: 15.380554 | J15: 15.347726 | K15: 4.5 | L15: Produce | M15: Dried fruit and bean curd | N15: Mayumi's | O15: Osaka | P15: Japan
A16: 15 | B16: Genen Shouyu | C16: 24 - 250 ml bottles | D16: 39 | E16: 0 | F16: 5 | G16: 0 | H16: 8.7559169 | I16: 10.783947 | J16: 11 | K16: 4.5 | L16: Condiments | M16: Sweet and savory sauces relishes spreads and seasonings | N16: Mayumi's | O16: Osaka | P16: Japan
A17: 16 | B17: Pavlova | C17: 32 - 500 g boxes | D17: 29 | E17: 0 | F17: 10 | G17: 0 | H17: 9.8065801 | I17: 11.985048 | J17: 12.68284 | K17: 4 | L17: Confections | M17: Desserts candies and sweet breads | N17: Pavlova Ltd. | O17: Melbourne | P17: Australia
A18: 17 | B18: Alice Mutton | C18: 20 - 1 kg tins | D18: 0 | E18: 0 | F18: 0 | G18: 1 | H18: 21.253774 | I18: 24.831305 | J18: 28.519163 | K18: 5 | L18: Meat/Poultry | M18: Prepared meats | N18: Pavlova Ltd. | O18: Melbourne | P18: Australia
A19: 18 | B19: Carnarvon Tigers | C19: 16 kg pkg. | D19: 42 | E19: 0 | F19: 0 | G19: 0 | H19: 32.463798 | I19: 39.519667 | J19: 41.27005 | K19: 4.5 | L19: Seafood | M19: Seaweed and fish | N19: Pavlova Ltd. | O19: Melbourne | P19: Australia
A20: 19 | B20: Teatime Chocolate Biscuits | C20: 10 boxes x 12 pieces | D20: 25 | E20: 0 | F20: 5 | G20: 0 | H20: 5.5812009 | I20: 5.9018837 | J20: 6.769657 | K20: 4 | L20: Confections | M20: Desserts candies and sweet breads | N20: Specialty Biscuits Ltd. | O20: Manchester | P20: UK
A21: 20 | B21: Sir Rodney's Marmalade | C21: 30 gift boxes | D21: 40 | E21: 0 | F21: 0 | G21: 0 | H21: 45.942474 | I21: 57.293421 | J21: 62.825376 | K21: 4.5 | L21: Confections | M21: Desserts candies and sweet breads | N21: Specialty Biscuits Ltd. | O21: Manchester | P21: UK
... A48: 47 | B48: Zaanse koeken | C48: 10 - 4 oz boxes | D48: 36 | E48: 0 | F48: 0 | G48: 0 | H48: 4.7389004 | I48: 6.5770883 | J48: 6.6351308 | K48: 3.5 | L48: Confections | M48: Desserts candies and sweet breads | N48: Zaanse Snoepfabriek | O48: Zaandam | P48: Netherlands
A49: 48 | B49: Chocolade | C49: 10 pkgs. | D49: 15 | E49: 70 | F49: 25 | G49: 0 | I49: 8.0796717 | J49: 8.207116 | K49: 4 | L49: Confections | M49: Desserts candies and sweet breads | N49: Zaanse Snoepfabriek | O49: Zaandam | P49: Netherlands
A50: 49 | B50: Maxilaku | C50: 24 - 50 g pkgs. | D50: 10 | E50: 60 | F50: 15 | G50: 0 | H50: 12.566636 | I50: 13.041123 | J50: 15.074599 | K50: 4.5 | L50: Confections | M50: Desserts candies and sweet breads | N50: Karkki Oy | O50: Lappeenranta | P50: Finland
A51: 50 | B51: Valkoinen suklaa | C51: 12 - 100 g bars | D51: 65 | E51: 0 | F51: 30 | G51: 0 | H51: 9.6822786 | I51: 11.160214 | J51: 12.642922 | K51: 4.5 | L51: Confections | M51: Desserts candies and sweet breads | N51: Karkki Oy | O51: Lappeenranta | P51: Finland
A52: 51 | B52: Manjimup Dried Apples | C52: 50 - 300 g pkgs. | D52: 20 | E52: 0 | F52: 10 | G52: 0 | H52: 28.875322 | I52: 36.88798 | J52: 39.514165 | K52: 4.5 | L52: Produce | M52: Dried fruit and bean curd | N52: G'day Mate | O52: Sydney | P52: Australia
A53: 52 | B53: Filo Mix | C53: 16 - 2 kg boxes | D53: 38 | E53: 0 | F53: 25 | G53: 0 | H53: 3.8535 | I53: 5.0017067 | J53: 5.2222234 | K53: 1.5 | L53: Grains/Cereals | M53: Breads crackers pasta and cereal | N53: G'day Mate | O53: Sydney | P53: Australia
A54: 53 | B54: Perth Pasties | C54: 48 pieces | D54: 0 | E54: 0 | F54: 0 | G54: 1 | H54: 18.33322 | I54: 21.814916 | J54: 22.926371 | K54: 4 | L54: Meat/Poultry | M54: Prepared meats | N54: G'day Mate | O54: Sydney | P54: Australia
A55: 54 | B55: Tourtière | C55: 16 pies | D55: 21 | E55: 0 | F55: 10 | G55: 0 | H55: 4.3098489 | I55: 4.9244478 | J55: 4.8847165 | K55: 5 | L55: Meat/Poultry | M55: Prepared meats | N55: Ma Maison | O55: Montréal | P55: Canada
A56: 55 | B56: Pâté chinois | C56: 24 boxes x 2 pies | D56: 115 | E56: 0 | F56: 20 | G56: 0 | H56: 12.974961 | I56: 14.923988 | J56: 16.959985 | K56: 4.5 | L56: Meat/Poultry | M56: Prepared meats | N56: Ma Maison | O56: Montréal | P56: Canada
A57: 56 | B57: Gnocchi di nonna Alice | C57: 24 - 250 g pkgs. | D57: 21 | E57: 10 | F57: 30 | G57: 0 | H57: 21.504006 | I57: 24.283424 | J57: 27.539159 | K57: 5 | L57: Grains/Cereals | M57: Breads crackers pasta and cereal | N57: Pasta Buttini s.r.l. | O57: Salerno | P57: Italy
A58: 57 | B58: Ravioli Angelo | C58: 24 - 250 g pkgs. | D58: 36 | E58: 0 | F58: 20 | G58: 0 | H58: 11.229508 | I58: 13.018709 | J58: 14.295348 | K58: 5 | L58: Grains/Cereals | M58: Breads crackers pasta and cereal | N58: Pasta Buttini s.r.l. | O58: Salerno | P58: Italy
A59: 58 | B59: Escargots de Bourgogne | C59: 24 pieces | D59: 62 | E59: 0 | F59: 20 | G59: 0 | H59: 6.3889393 | I59: 8.2084464 | J59: 8.6831022 | K59: 4.5 | L59: Seafood | M59: Seaweed and fish | N59: Escargots Nouveaux | O59: Montceau | P59: France
A60: 59 | B60: Raclette Courdavault | C60: 5 kg pkg. | D60: 79 | E60: 0 | F60: 0 | G60: 0 | H60: 29.20352 | I60: 35.204726 | J60: 36.748637 | K60: 4 | L60: Dairy Products | M60: Cheeses | N60: Gai pâturage | O60: Annecy | P60: France
A61: 60 | B61: Camembert Pierrot | C61: 15 - 300 g rounds | D61: 19 | E61: 0 | F61: 0 | G61: 0 | H61: 17.665635 | I61: 22.770983 | J61: 22.490912 | K61: 5 | L61: Dairy Products | M61: Cheeses | N61: Gai pâturage | O61: Annecy | P61: France
A62: 61 | B62: Sirop d'érable | C62: 24 - 500 ml bottles | D62: 113 | E62: 0 | F62: 25 | G62: 0 | I62: 17.199454 | J62: 18.744874 | K62: 4.5 | L62: Condiments | M62: Sweet and savory sauces relishes spreads and seasonings | N62: Forêts d'érables | O62: Ste-Hyacinthe | P62: Canada
A63: 62 | B63: Tarte au sucre | C63: 48 pies | D63: 17 | E63: 0 | F63: 0 | G63: 0 | H63: 29.359633 | I63: 35.347928 | J63: 34.88145 | K63: 5 | L63: Confections | M63: Desserts candies and sweet breads | N63: Forêts d'érables | O63: Ste-Hyacinthe | P63: Canada
A64: 63 | B64: Vegie-spread | C64: 15 - 625 g jars | D64: 24 | E64: 0 | F64: 5 | G64: 0 | H64: 23.813723 | I64: 27.722257 | J64: 32.591986 | K64: 5 | L64: Condiments | M64: Sweet and savory sauces relishes spreads and seasonings | N64: Pavlova Ltd. | O64: Melbourne | P64: Australia
A65: 64 | B65: Lukas' leckere Sauerteigweggla | C65: 20 bags x 4 pieces | D65: 22 | E65: 80 | F65: 30 | G65: 0 | H65: 19.369823 | I65: 21.885727 | J65: 22.724343 | K65: 5 | L65: Grains/Cereals | M65: Breads crackers pasta and cereal | N65: Plutzer Lebensmittelgroßmärkte AG | O65: Frankfurt | P65: Germany
A66: 65 | B66: Louisiana Fiery Hot Pepper Sauce | C66: 32 - 8 oz bottles | D66: 76 | E66: 0 | F66: 0 | G66: 0 | H66: 11.174102 | I66: 13.211222 | J66: 14.507382 | K66: 5 | L66: Condiments | M66: Sweet and savory sauces relishes spreads and seasonings | N66: New Orleans Cajun Delights | O66: New Orleans | P66: USA
...

Sheet 3 customers
A1: customerID | B1: companyName | C1: contactName | D1: contactTitle | E1: address | F1: city | G1: region | H1: postalCode | I1: country | J1: phone
A2: ALFKI | B2: Alfreds Futterkiste | C2: Maria Anders | D2: Sales Representative | E2: Obere Str. 57 | F2: Berlin | G2: NULL | H2: 12209 | I2: Germany | J2: 030-0074321
A3: ANATR | B3: Ana Trujillo Emparedados y helados | C3: Ana Trujillo | D3: Owner | E3: Avda. de la Constitución 2222 | F3: México D.F. | G3: NULL | H3: 05021 | I3: Mexico | J3: (5) 555-4729
A4: ANTON | B4: Antonio Moreno Taquería | C4: Antonio Moreno | D4: Owner | E4: Mataderos 2312 | F4: México D.F. | G4: NULL | H4: 05023 | I4: Mexico | J4: (5) 555-3932
A5: AROUT | B5: Around the Horn | C5: Thomas Hardy | D5: Sales Representative | E5: 120 Hanover Sq. | F5: London | G5: NULL | H5: WA1 1DP | I5: UK | J5: (171) 555-7788
A6: BERGS | B6: Berglunds snabbköp | C6: Christina Berglund | D6: Order Administrator | E6: Berguvsvägen 8 | F6: Luleå | G6: NULL | H6: S-958 22 | I6: Sweden | J6: 0921-12 34 65
A7: BLAUS | B7: Blauer See Delikatessen | C7: Hanna Moos | D7: Sales Representative | E7: Forsterstr. 57 | F7: Mannheim | G7: NULL | H7: 68306 | I7: Germany | J7: 0621-08460
A8: BLONP | B8: Blondesddsl père et fils | C8: Frédérique Citeaux | D8: Marketing Manager | E8: 24 place Kléber | F8: Strasbourg | G8: NULL | H8: 67000 | I8: France | J8: 88.60.15.31
A9: BOLID | B9: Bólido Comidas preparadas | C9: Martín Sommer | D9: Owner | E9: 67C Araquil | F9: Madrid | G9: NULL | H9: 28023 | I9: Spain | J9: (91) 555 22 82
A10: BONAP | B10: Bon app' | C10: Laurence Lebihan | D10: Owner | E10: 12 rue des Bouchers | F10: Marseille | G10: NULL | H10: 13008 | I10: France | J10: 91.24.45.40
A11: BOTTM | B11: Bottom-Dollar Markets | C11: Elizabeth Lincoln | D11: Accounting Manager | E11: 23 Tsawassen Blvd. | F11: Tsawassen | G11: BC | H11: T2F 8M4 | I11: Canada | J11: (604) 555-4729
A12: BSBEV | B12: B's Beverages | C12: Victoria Ashworth | D12: Sales Representative | E12: Fauntleroy Circus | F12: London | G12: NULL | H12: EC2 5NT | I12: UK | J12: (171) 555-1212
... A92: WOLZA | B92: Wolski Zajazd | C92: Zbyszek Piestrzeniewicz | D92: Owner | E92: ul. Filtrowa 68 | F92: Warszawa | G92: NULL | H92: 01-012 | I92: Poland | J92: (26) 642-7012

Sheet analysis-dynamic
A1: orderID | B1: customerID | C1: customerName | D1: orderDate | E1: orderCount | F1: sinceLastOrder | G1: customerStatus | H1: productID | I1: productName | J1: productCategory | K1: productStatus | L1: productCost | M1: orderPrice | N1: productMarkup | O1: orderQuantity | P1: discountApllied | Q1: orderTotal | R1: revenue | S1: profit | T1: profitMargin
A2: 10248 | B2: VINET | C2: =VLOOKUP(dynamic[customerID],customers[],2,FALSE) -> Vins et alcools Chevalier | D2: 44746 | E2: =IFERROR(__xludf.DUMMYFUNCTION("COUNTUNIQUEIFS($A$2:$A2,$B$2:$B2,B2)"),1.0) -> 1 | F2: =IF(E2=1, 0, D2 - INDEX($D$2:$D2,MATCH(1, ($B$2:$B2=B2)*($E$2:$E2=E2-1), 0))) -> 0 | G2: =IF(MINIFS(dynamic[orderDate], dynamic[customerID], B2) >= DATE(2024,4,30)-120, "New", IF(MAXIFS(dynamic[orderCount], dynamic[customerID], B2)<=2, IF((DATE(2024,4,30) - MAXIFS(dynamic[orderDate], dynamic[customerID], B2)) > 180, "Non-Returning", "Dormant"), IF(AND(MAX(dynamic[sinceLastOrder]) > 365, (DATE(2024,4,30) - MAXIFS(dynamic[orderDate], dynamic[customerID], B2)) > 180), "Dormant", "Regular"))) -> Regular | H2: 11 | I2: =VLOOKUP(dynamic[productID],products[],2,FALSE) -> Queso Cabrales | J2: =VLOOKUP(dynamic[productID],products[],12,FALSE) -> Dairy Products | K2: =IF(VLOOKUP(dynamic[productID],products[],7,FALSE)=1,"Discontinued","Current") -> Current | L2: =VLOOKUP(dynamic[productID],products[],IF(YEAR(dynamic[orderDate])=2022,8,IF(YEAR(dynamic[orderDate])=2023,9,IF(YEAR(dynamic[orderDate])=2024,10,NA))),FALSE) -> 10.582311 | M2: 14 | N2: =(dynamic[orderPrice]-dynamic[productCost])/dynamic[productCost] -> 0.32296245 | O2: 12 | P2: 0 | Q2: =dynamic[orderPrice]*dynamic[orderQuantity] -> 168 | R2: =dynamic[orderTotal]*(1-dynamic[discountApllied]) -> 168 | S2: =dynamic[revenue]-(dynamic[productCost]*dynamic[orderQuantity]) -> 41.012268 | T2: =IFERROR(dynamic[profit]/dynamic[revenue], 0) -> 0.24412064
A3: 10248 | B3: VINET | C3: =VLOOKUP(dynamic[customerID],customers[],2,FALSE) -> Vins et alcools Chevalier | D3: 44746 | E3: =IFERROR(__xludf.DUMMYFUNCTION("COUNTUNIQUEIFS($A$2:$A3,$B$2:$B3,B3)"),1.0) -> 1 | F3: =IF(E3=1, 0, D3 - INDEX($D$2:$D3,MATCH(1, ($B$2:$B3=B3)*($E$2:$E3=E3-1), 0))) -> 0 | G3: =IF(MINIFS(dynamic[orderDate], dynamic[customerID], B3) >= DATE(2024,4,30)-120, "New", IF(MAXIFS(dynamic[orderCount], dynamic[customerID], B3)<=2, IF((DATE(2024,4,30) - MAXIFS(dynamic[orderDate], dynamic[customerID], B3)) > 180, "Non-Returning", "Dormant"), IF(AND(MAX(dynamic[sinceLastOrder]) > 365, (DATE(2024,4,30) - MAXIFS(dynamic[orderDate], dynamic[customerID], B3)) > 180), "Dormant", "Regular"))) -> Regular | H3: 42 | I3: =VLOOKUP(dynamic[productID],products[],2,FALSE) -> Singaporean Hokkien Fried Mee | J3: =VLOOKUP(dynamic[productID],products[],12,FALSE) -> Grains/Cereals | K3: =IF(VLOOKUP(dynamic[productID],products[],7,FALSE)=1,"Discontinued","Current") -> Discontinued | L3: =VLOOKUP(dynamic[productID],products[],IF(YEAR(dynamic[orderDate])=2022,8,IF(YEAR(dynamic[orderDate])=2023,9,IF(YEAR(dynamic[orderDate])=2024,10,NA))),FALSE) -> 7.8184259 | M3: 9.8 | N3: =(dynamic[orderPrice]-dynamic[productCost])/dynamic[productCost] -> 0.25344924 | O3: 10 | P3: 0 | Q3: =dynamic[orderPrice]*dynamic[orderQuantity] -> 98 | R3: =dynamic[orderTotal]*(1-dynamic[discountApllied]) -> 98 | S3: =dynamic[revenue]-(dynamic[productCost]*dynamic[orderQuantity]) -> 19.815741 | T3: =IFERROR(dynamic[profit]/dynamic[revenue], 0) -> 0.20220144
A4: 10248 | B4: VINET | C4: =VLOOKUP(dynamic[customerID],customers[],2,FALSE) -> Vins et alcools Chevalier | D4: 44746 | E4: =IFERROR(__xludf.DUMMYFUNCTION("COUNTUNIQUEIFS($A$2:$A4,$B$2:$B4,B4)"),1.0) -> 1 | F4: =IF(E4=1, 0, D4 - INDEX($D$2:$D4,MATCH(1, ($B$2:$B4=B4)*($E$2:$E4=E4-1), 0))) -> 0 | G4: =IF(MINIFS(dynamic[orderDate], dynamic[customerID], B4) >= DATE(2024,4,30)-120, "New", IF(MAXIFS(dynamic[orderCount], dynamic[customerID], B4)<=2, IF((DATE(2024,4,30) - MAXIFS(dynamic[orderDate], dynamic[customerID], B4)) > 180, "Non-Returning", "Dormant"), IF(AND(MAX(dynamic[sinceLastOrder]) > 365, (DATE(2024,4,30) - MAXIFS(dynamic[orderDate], dynamic[customerID], B4)) > 180), "Dormant", "Regular"))) -> Regular | H4: 72 | I4: =VLOOKUP(dynamic[productID],products[],2,FALSE) -> Mozzarella di Giovanni | J4: =VLOOKUP(dynamic[productID],products[],12,FALSE) -> Dairy Products | K4: =IF(VLOOKUP(dynamic[productID],products[],7,FALSE)=1,"Discontinued","Current") -> Current | L4: =VLOOKUP(dynamic[productID],products[],IF(YEAR(dynamic[orderDate])=2022,8,IF(YEAR(dynamic[orderDate])=2023,9,IF(YEAR(dynamic[orderDate])=2024,10,NA))),FALSE) -> 19.208293 | M4: 34.8 | N4: =(dynamic[orderPrice]-dynamic[productCost])/dynamic[productCost] -> 0.81171744 | O4: 5 | P4: 0 | Q4: =dynamic[orderPrice]*dynamic[orderQuantity] -> 174 | R4: =dynamic[orderTotal]*(1-dynamic[discountApllied]) -> 174 | S4: =dynamic[revenue]-(dynamic[productCost]*dynamic[orderQuantity]) -> 77.958533 | T4: =IFERROR(dynamic[profit]/dynamic[revenue], 0) -> 0.44803755
A5: 10249 | B5: TOMSP | C5: =VLOOKUP(dynamic[customerID],customers[],2,FALSE) -> Toms Spezialitäten | D5: 44747 | E5: =IFERROR(__xludf.DUMMYFUNCTION("COUNTUNIQUEIFS($A$2:$A5,$B$2:$B5,B5)"),1.0) -> 1 | F5: =IF(E5=1, 0, D5 - INDEX($D$2:$D5,MATCH(1, ($B$2:$B5=B5)*($E$2:$E5=E5-1), 0))) -> 0 | G5: =IF(MINIFS(dynamic[orderDate], dynamic[customerID], B5) >= DATE(2024,4,30)-120, "New", IF(MAXIFS(dynamic[orderCount], dynamic[customerID], B5)<=2, IF((DATE(2024,4,30) - MAXIFS(dynamic[orderDate], dynamic[customerID], B5)) > 180, "Non-Returning", "Dormant"), IF(AND(MAX(dynamic[sinceLastOrder]) > 365, (DATE(2024,4,30) - MAXIFS(dynamic[orderDate], dynamic[customerID], B5)) > 180), "Dormant", "Regular"))) -> Regular | H5: 14 | I5: =VLOOKUP(dynamic[productID],products[],2,FALSE) -> Tofu | J5: =VLOOKUP(dynamic[productID],products[],12,FALSE) -> Produce | K5: =IF(VLOOKUP(dynamic[productID],products[],7,FALSE)=1,"Discontinued","Current") -> Current | L5: =VLOOKUP(dynamic[productID],products[],IF(YEAR(dynamic[orderDate])=2022,8,IF(YEAR(dynamic[orderDate])=2023,9,IF(YEAR(dynamic[orderDate])=2024,10,NA))),FALSE) -> 13.952541 | M5: 18.6 | N5: =(dynamic[orderPrice]-dynamic[productCost])/dynamic[productCost] -> 0.33309053 | O5: 9 | P5: 0 | Q5: =dynamic[orderPrice]*dynamic[orderQuantity] -> 167.4 | R5: =dynamic[orderTotal]*(1-dynamic[discountApllied]) -> 167.4 | S5: =dynamic[revenue]-(dynamic[productCost]*dynamic[orderQuantity]) -> 41.827133 | T5: =IFERROR(dynamic[profit]/dynamic[revenue], 0) -> 0.2498634
A6: 10249 | B6: TOMSP | C6: =VLOOKUP(dynamic[customerID],customers[],2,FALSE) -> Toms Spezialitäten | D6: 44747 | E6: =IFERROR(__xludf.DUMMYFUNCTION("COUNTUNIQUEIFS($A$2:$A6,$B$2:$B6,B6)"),1.0) -> 1 | F6: =IF(E6=1, 0, D6 - INDEX($D$2:$D6,MATCH(1, ($B$2:$B6=B6)*($E$2:$E6=E6-1), 0))) -> 0 | G6: =IF(MINIFS(dynamic[orderDate], dynamic[customerID], B6) >= DATE(2024,4,30)-120, "New", IF(MAXIFS(dynamic[orderCount], dynamic[customerID], B6)<=2, IF((DATE(2024,4,30) - MAXIFS(dynamic[orderDate], dynamic[customerID], B6)) > 180, "Non-Returning", "Dormant"), IF(AND(MAX(dynamic[sinceLastOrder]) > 365, (DATE(2024,4,30) - MAXIFS(dynamic[orderDate], dynamic[customerID], B6)) > 180), "Dormant", "Regular"))) -> Regular | H6: 51 | I6: =VLOOKUP(dynamic[productID],products[],2,FALSE) -> Manjimup Dried Apples | J6: =VLOOKUP(dynamic[productID],products[],12,FALSE) -> Produce | K6: =IF(VLOOKUP(dynamic[productID],products[],7,FALSE)=1,"Discontinued","Current") -> Current | L6: =VLOOKUP(dynamic[productID],products[],IF(YEAR(dynamic[orderDate])=2022,8,IF(YEAR(dynamic[orderDate])=2023,9,IF(YEAR(dynamic[orderDate])=2024,10,NA))),FALSE) -> 28.875322 | M6: 42.4 | N6: =(dynamic[orderPrice]-dynamic[productCost])/dynamic[productCost] -> 0.46838192 | O6: 40 | P6: 0 | Q6: =dynamic[orderPrice]*dynamic[orderQuantity] -> 1696 | R6: =dynamic[orderTotal]*(1-dynamic[discountApllied]) -> 1696 | S6: =dynamic[revenue]-(dynamic[productCost]*dynamic[orderQuantity]) -> 540.98714 | T6: =IFERROR(dynamic[profit]/dynamic[revenue], 0) -> 0.31897827
A7: 10250 | B7: HANAR | C7: =VLOOKUP(dynamic[customerID],customers[],2,FALSE) -> Hanari Carnes | D7: 44750 | E7: =IFERROR(__xludf.DUMMYFUNCTION("COUNTUNIQUEIFS($A$2:$A7,$B$2:$B7,B7)"),1.0) -> 1 | F7: =IF(E7=1, 0, D7 - INDEX($D$2:$D7,MATCH(1, ($B$2:$B7=B7)*($E$2:$E7=E7-1), 0))) -> 0 | G7: =IF(MINIFS(dynamic[orderDate], dynamic[customerID], B7) >= DATE(2024,4,30)-120, "New", IF(MAXIFS(dynamic[orderCount], dynamic[customerID], B7)<=2, IF((DATE(2024,4,30) - MAXIFS(dynamic[orderDate], dynamic[customerID], B7)) > 180, "Non-Returning", "Dormant"), IF(AND(MAX(dynamic[sinceLastOrder]) > 365, (DATE(2024,4,30) - MAXIFS(dynamic[orderDate], dynamic[customerID], B7)) > 180), "Dormant", "Regular"))) -> Regular | H7: 41 | I7: =VLOOKUP(dynamic[productID],products[],2,FALSE) -> Jack's New England Clam Chowder | J7: =VLOOKUP(dynamic[productID],products[],12,FALSE) -> Seafood | K7: =IF(VLOOKUP(dynamic[productID],products[],7,FALSE)=1,"Discontinued","Current") -> Current | L7: =VLOOKUP(dynamic[productID],products[],IF(YEAR(dynamic[orderDate])=2022,8,IF(YEAR(dynamic[orderDate])=2023,9,IF(YEAR(dynamic[orderDate])=2024,10,NA))),FALSE) -> 5.1701987 | M7: 7.7 | N7: =(dynamic[orderPrice]-dynamic[productCost])/dynamic[productCost] -> 0.48930445 | O7: 10 | P7: 0 | Q7: =dynamic[orderPrice]*dynamic[orderQuantity] -> 77 | R7: =dynamic[orderTotal]*(1-dynamic[discountApllied]) -> 77 | S7: =dynamic[revenue]-(dynamic[productCost]*dynamic[orderQuantity]) -> 25.298013 | T7: =IFERROR(dynamic[profit]/dynamic[revenue], 0) -> 0.32854562
A8: 10250 | B8: HANAR | C8: =VLOOKUP(dynamic[customerID],customers[],2,FALSE) -> Hanari Carnes | D8: 44750 | E8: =IFERROR(__xludf.DUMMYFUNCTION("COUNTUNIQUEIFS($A$2:$A8,$B$2:$B8,B8)"),1.0) -> 1 | F8: =IF(E8=1, 0, D8 - INDEX($D$2:$D8,MATCH(1, ($B$2:$B8=B8)*($E$2:$E8=E8-1), 0))) -> 0 | G8: =IF(MINIFS(dynamic[orderDate], dynamic[customerID], B8) >= DATE(2024,4,30)-120, "New", IF(MAXIFS(dynamic[orderCount], dynamic[customerID], B8)<=2, IF((DATE(2024,4,30) - MAXIFS(dynamic[orderDate], dynamic[customerID], B8)) > 180, "Non-Returning", "Dormant"), IF(AND(MAX(dynamic[sinceLastOrder]) > 365, (DATE(2024,4,30) - MAXIFS(dynamic[orderDate], dynamic[customerID], B8)) > 180), "Dormant", "Regular"))) -> Regular | H8: 51 | I8: =VLOOKUP(dynamic[productID],products[],2,FALSE) -> Manjimup Dried Apples | J8: =VLOOKUP(dynamic[productID],products[],12,FALSE) -> Produce | K8: =IF(VLOOKUP(dynamic[productID],products[],7,FALSE)=1,"Discontinued","Current") -> Current | L8: =VLOOKUP(dynamic[productID],products[],IF(YEAR(dynamic[orderDate])=2022,8,IF(YEAR(dynamic[orderDate])=2023,9,IF(YEAR(dynamic[orderDate])=2024,10,NA))),FALSE) -> 28.875322 | M8: 42.4 | N8: =(dynamic[orderPrice]-dynamic[productCost])/dynamic[productCost] -> 0.46838192 | O8: 35 | P8: 0.15 | Q8: =dynamic[orderPrice]*dynamic[orderQuantity] -> 1484 | R8: =dynamic[orderTotal]*(1-dynamic[discountApllied]) -> 1261.4 | S8: =dynamic[revenue]-(dynamic[productCost]*dynamic[orderQuantity]) -> 250.76375 | T8: =IFERROR(dynamic[profit]/dynamic[revenue], 0) -> 0.19879796
A9: 10250 | B9: HANAR | C9: =VLOOKUP(dynamic[customerID],customers[],2,FALSE) -> Hanari Carnes | D9: 44750 | E9: =IFERROR(__xludf.DUMMYFUNCTION("COUNTUNIQUEIFS($A$2:$A9,$B$2:$B9,B9)"),1.0) -> 1 | F9: =IF(E9=1, 0, D9 - INDEX($D$2:$D9,MATCH(1, ($B$2:$B9=B9)*($E$2:$E9=E9-1), 0))) -> 0 | G9: =IF(MINIFS(dynamic[orderDate], dynamic[customerID], B9) >= DATE(2024,4,30)-120, "New", IF(MAXIFS(dynamic[orderCount], dynamic[customerID], B9)<=2, IF((DATE(2024,4,30) - MAXIFS(dynamic[orderDate], dynamic[customerID], B9)) > 180, "Non-Returning", "Dormant"), IF(AND(MAX(dynamic[sinceLastOrder]) > 365, (DATE(2024,4,30) - MAXIFS(dynamic[orderDate], dynamic[customerID], B9)) > 180), "Dormant", "Regular"))) -> Regular | H9: 65 | I9: =VLOOKUP(dynamic[productID],products[],2,FALSE) -> Louisiana Fiery Hot Pepper Sauce | J9: =VLOOKUP(dynamic[productID],products[],12,FALSE) -> Condiments | K9: =IF(VLOOKUP(dynamic[productID],products[],7,FALSE)=1,"Discontinued","Current") -> Current | L9: =VLOOKUP(dynamic[productID],products[],IF(YEAR(dynamic[orderDate])=2022,8,IF(YEAR(dynamic[orderDate])=2023,9,IF(YEAR(dynamic[orderDate])=2024,10,NA))),FALSE) -> 11.174102 | M9: 16.8 | N9: =(dynamic[orderPrice]-dynamic[productCost])/dynamic[productCost] -> 0.50347652 | O9: 15 | P9: 0.15 | Q9: =dynamic[orderPrice]*dynamic[orderQuantity] -> 252 | R9: =dynamic[orderTotal]*(1-dynamic[discountApllied]) -> 214.2 | S9: =dynamic[revenue]-(dynamic[productCost]*dynamic[orderQuantity]) -> 46.588469 | T9: =IFERROR(dynamic[profit]/dynamic[revenue], 0) -> 0.21749986
A10: 10251 | B10: VICTE | C10: =VLOOKUP(dynamic[customerID],customers[],2,FALSE) -> Victuailles en stock | D10: 44750 | E10: =IFERROR(__xludf.DUMMYFUNCTION("COUNTUNIQUEIFS($A$2:$A10,$B$2:$B10,B10)"),1.0) -> 1 | F10: =IF(E10=1, 0, D10 - INDEX($D$2:$D10,MATCH(1, ($B$2:$B10=B10)*($E$2:$E10=E10-1), 0))) -> 0 | G10: =IF(MINIFS(dynamic[orderDate], dynamic[customerID], B10) >= DATE(2024,4,30)-120, "New", IF(MAXIFS(dynamic[orderCount], dynamic[customerID], B10)<=2, IF((DATE(2024,4,30) - MAXIFS(dynamic[orderDate], dynamic[customerID], B10)) > 180, "Non-Returning", "Dormant"), IF(AND(MAX(dynamic[sinceLastOrder]) > 365, (DATE(2024,4,30) - MAXIFS(dynamic[orderDate], dynamic[customerID], B10)) > 180), "Dormant", "Regular"))) -> Regular | H10: 22 | I10: =VLOOKUP(dynamic[productID],products[],2,FALSE) -> Gustaf's Knäckebröd | J10: =VLOOKUP(dynamic[productID],products[],12,FALSE) -> Grains/Cereals | K10: =IF(VLOOKUP(dynamic[productID],products[],7,FALSE)=1,"Discontinued","Current") -> Current | L10: =VLOOKUP(dynamic[productID],products[],IF(YEAR(dynamic[orderDate])=2022,8,IF(YEAR(dynamic[orderDate])=2023,9,IF(YEAR(dynamic[orderDate])=2024,10,NA))),FALSE) -> 11.700492 | M10: 16.8 | N10: =(dynamic[orderPrice]-dynamic[productCost])/dynamic[productCost] -> 0.43583704 | O10: 6 | P10: 0.05 | Q10: =dynamic[orderPrice]*dynamic[orderQuantity] -> 100.8 | R10: =dynamic[orderTotal]*(1-dynamic[discountApllied]) -> 95.76 | S10: =dynamic[revenue]-(dynamic[productCost]*dynamic[orderQuantity]) -> 25.557047 | T10: =IFERROR(dynamic[profit]/dynamic[revenue], 0) -> 0.26688646
A11: 10251 | B11: VICTE | C11: =VLOOKUP(dynamic[customerID],customers[],2,FALSE) -> Victuailles en stock | D11: 44750 | E11: =IFERROR(__xludf.DUMMYFUNCTION("COUNTUNIQUEIFS($A$2:$A11,$B$2:$B11,B11)"),1.0) -> 1 | F11: =IF(E11=1, 0, D11 - INDEX($D$2:$D11,MATCH(1, ($B$2:$B11=B11)*($E$2:$E11=E11-1), 0))) -> 0 | G11: =IF(MINIFS(dynamic[orderDate], dynamic[customerID], B11) >= DATE(2024,4,30)-120, "New", IF(MAXIFS(dynamic[orderCount], dynamic[customerID], B11)<=2, IF((DATE(2024,4,30) - MAXIFS(dynamic[orderDate], dynamic[customerID], B11)) > 180, "Non-Returning", "Dormant"), IF(AND(MAX(dynamic[sinceLastOrder]) > 365, (DATE(2024,4,30) - MAXIFS(dynamic[orderDate], dynamic[customerID], B11)) > 180), "Dormant", "Regular"))) -> Regular | H11: 57 | I11: =VLOOKUP(dynamic[productID],products[],2,FALSE) -> Ravioli Angelo | J11: =VLOOKUP(dynamic[productID],products[],12,FALSE) -> Grains/Cereals | K11: =IF(VLOOKUP(dynamic[productID],products[],7,FALSE)=1,"Discontinued","Current") -> Current | L11: =VLOOKUP(dynamic[productID],products[],IF(YEAR(dynamic[orderDate])=2022,8,IF(YEAR(dynamic[orderDate])=2023,9,IF(YEAR(dynamic[orderDate])=2024,10,NA))),FALSE) -> 11.229508 | M11: 15.6 | N11: =(dynamic[orderPrice]-dynamic[productCost])/dynamic[productCost] -> 0.38919715 | O11: 15 | P11: 0.05 | Q11: =dynamic[orderPrice]*dynamic[orderQuantity] -> 234 | R11: =dynamic[orderTotal]*(1-dynamic[discountApllied]) -> 222.3 | S11: =dynamic[revenue]-(dynamic[productCost]*dynamic[orderQuantity]) -> 53.857385 | T11: =IFERROR(dynamic[profit]/dynamic[revenue], 0) -> 0.24227344
A12: 10251 | B12: VICTE | C12: =VLOOKUP(dynamic[customerID],customers[],2,FALSE) -> Victuailles en stock | D12: 44750 | E12: =IFERROR(__xludf.DUMMYFUNCTION("COUNTUNIQUEIFS($A$2:$A12,$B$2:$B12,B12)"),1.0) -> 1 | F12: =IF(E12=1, 0, D12 - INDEX($D$2:$D12,MATCH(1, ($B$2:$B12=B12)*($E$2:$E12=E12-1), 0))) -> 0 | G12: =IF(MINIFS(dynamic[orderDate], dynamic[customerID], B12) >= DATE(2024,4,30)-120, "New", IF(MAXIFS(dynamic[orderCount], dynamic[customerID], B12)<=2, IF((DATE(2024,4,30) - MAXIFS(dynamic[orderDate], dynamic[customerID], B12)) > 180, "Non-Returning", "Dormant"), IF(AND(MAX(dynamic[sinceLastOrder]) > 365, (DATE(2024,4,30) - MAXIFS(dynamic[orderDate], dynamic[customerID], B12)) > 180), "Dormant", "Regular"))) -> Regular | H12: 65 | I12: =VLOOKUP(dynamic[productID],products[],2,FALSE) -> Louisiana Fiery Hot Pepper Sauce | J12: =VLOOKUP(dynamic[productID],products[],12,FALSE) -> Condiments | K12: =IF(VLOOKUP(dynamic[productID],products[],7,FALSE)=1,"Discontinued","Current") -> Current | L12: =VLOOKUP(dynamic[productID],products[],IF(YEAR(dynamic[orderDate])=2022,8,IF(YEAR(dynamic[orderDate])=2023,9,IF(YEAR(dynamic[orderDate])=2024,10,NA))),FALSE) -> 11.174102 | M12: 16.8 | N12: =(dynamic[orderPrice]-dynamic[productCost])/dynamic[productCost] -> 0.50347652 | O12: 20 | P12: 0 | Q12: =dynamic[orderPrice]*dynamic[orderQuantity] -> 336 | R12: =dynamic[orderTotal]*(1-dynamic[discountApllied]) -> 336 | S12: =dynamic[revenue]-(dynamic[productCost]*dynamic[orderQuantity]) -> 112.51796 | T12: =IFERROR(dynamic[profit]/dynamic[revenue], 0) -> 0.33487488
A13: 10252 | B13: SUPRD | C13: =VLOOKUP(dynamic[customerID],customers[],2,FALSE) -> Suprêmes délices | D13: 44751 | E13: =IFERROR(__xludf.DUMMYFUNCTION("COUNTUNIQUEIFS($A$2:$A13,$B$2:$B13,B13)"),1.0) -> 1 | F13: =IF(E13=1, 0, D13 - INDEX($D$2:$D13,MATCH(1, ($B$2:$B13=B13)*($E$2:$E13=E13-1), 0))) -> 0 | G13: =IF(MINIFS(dynamic[orderDate], dynamic[customerID], B13) >= DATE(2024,4,30)-120, "New", IF(MAXIFS(dynamic[orderCount], dynamic[customerID], B13)<=2, IF((DATE(2024,4,30) - MAXIFS(dynamic[orderDate], dynamic[customerID], B13)) > 180, "Non-Returning", "Dormant"), IF(AND(MAX(dynamic[sinceLastOrder]) > 365, (DATE(2024,4,30) - MAXIFS(dynamic[orderDate], dynamic[customerID], B13)) > 180), "Dormant", "Regular"))) -> Regular | H13: 20 | I13: =VLOOKUP(dynamic[productID],products[],2,FALSE) -> Sir Rodney's Marmalade | J13: =VLOOKUP(dynamic[productID],products[],12,FALSE) -> Confections | K13: =IF(VLOOKUP(dynamic[productID],products[],7,FALSE)=1,"Discontinued","Current") -> Current | L13: =VLOOKUP(dynamic[productID],products[],IF(YEAR(dynamic[orderDate])=2022,8,IF(YEAR(dynamic[orderDate])=2023,9,IF(YEAR(dynamic[orderDate])=2024,10,NA))),FALSE) -> 45.942474 | M13: 64.8 | N13: =(dynamic[orderPrice]-dynamic[productCost])/dynamic[productCost] -> 0.41045951 | O13: 40 | P13: 0.05 | Q13: =dynamic[orderPrice]*dynamic[orderQuantity] -> 2592 | R13: =dynamic[orderTotal]*(1-dynamic[discountApllied]) -> 2462.4 | S13: =dynamic[revenue]-(dynamic[productCost]*dynamic[orderQuantity]) -> 624.70102 | T13: =IFERROR(dynamic[profit]/dynamic[revenue], 0) -> 0.253696
A14: 10252 | B14: SUPRD | C14: =VLOOKUP(dynamic[customerID],customers[],2,FALSE) -> Suprêmes délices | D14: 44751 | E14: =IFERROR(__xludf.DUMMYFUNCTION("COUNTUNIQUEIFS($A$2:$A14,$B$2:$B14,B14)"),1.0) -> 1 | F14: =IF(E14=1, 0, D14 - INDEX($D$2:$D14,MATCH(1, ($B$2:$B14=B14)*($E$2:$E14=E14-1), 0))) -> 0 | G14: =IF(MINIFS(dynamic[orderDate], dynamic[customerID], B14) >= DATE(2024,4,30)-120, "New", IF(MAXIFS(dynamic[orderCount], dynamic[customerID], B14)<=2, IF((DATE(2024,4,30) - MAXIFS(dynamic[orderDate], dynamic[customerID], B14)) > 180, "Non-Returning", "Dormant"), IF(AND(MAX(dynamic[sinceLastOrder]) > 365, (DATE(2024,4,30) - MAXIFS(dynamic[orderDate], dynamic[customerID], B14)) > 180), "Dormant", "Regular"))) -> Regular | H14: 33 | I14: =VLOOKUP(dynamic[productID],products[],2,FALSE) -> Geitost | J14: =VLOOKUP(dynamic[productID],products[],12,FALSE) -> Dairy Products | K14: =IF(VLOOKUP(dynamic[productID],products[],7,FALSE)=1,"Discontinued","Current") -> Current | L14: =VLOOKUP(dynamic[productID],products[],IF(YEAR(dynamic[orderDate])=2022,8,IF(YEAR(dynamic[orderDate])=2023,9,IF(YEAR(dynamic[orderDate])=2024,10,NA))),FALSE) -> 1.3938474 | M14: 2 | N14: =(dynamic[orderPrice]-dynamic[productCost])/dynamic[productCost] -> 0.43487727 | O14: 25 | P14: 0.05 | Q14: =dynamic[orderPrice]*dynamic[orderQuantity] -> 50 | R14: =dynamic[orderTotal]*(1-dynamic[discountApllied]) -> 47.5 | S14: =dynamic[revenue]-(dynamic[productCost]*dynamic[orderQuantity]) -> 12.653814 | T14: =IFERROR(dynamic[profit]/dynamic[revenue], 0) -> 0.26639609
A15: 10252 | B15: SUPRD | C15: =VLOOKUP(dynamic[customerID],customers[],2,FALSE) -> Suprêmes délices | D15: 44751 | E15: =IFERROR(__xludf.DUMMYFUNCTION("COUNTUNIQUEIFS($A$2:$A15,$B$2:$B15,B15)"),1.0) -> 1 | F15: =IF(E15=1, 0, D15 - INDEX($D$2:$D15,MATCH(1, ($B$2:$B15=B15)*($E$2:$E15=E15-1), 0))) -> 0 | G15: =IF(MINIFS(dynamic[orderDate], dynamic[customerID], B15) >= DATE(2024,4,30)-120, "New", IF(MAXIFS(dynamic[orderCount], dynamic[customerID], B15)<=2, IF((DATE(2024,4,30) - MAXIFS(dynamic[orderDate], dynamic[customerID], B15)) > 180, "Non-Returning", "Dormant"), IF(AND(MAX(dynamic[sinceLastOrder]) > 365, (DATE(2024,4,30) - MAXIFS(dynamic[orderDate], dynamic[customerID], B15)) > 180), "Dormant", "Regular"))) -> Regular | H15: 60 | I15: =VLOOKUP(dynamic[productID],products[],2,FALSE) -> Camembert Pierrot | J15: =VLOOKUP(dynamic[productID],products[],12,FALSE) -> Dairy Products | K15: =IF(VLOOKUP(dynamic[productID],products[],7,FALSE)=1,"Discontinued","Current") -> Current | L15: =VLOOKUP(dynamic[productID],products[],IF(YEAR(dynamic[orderDate])=2022,8,IF(YEAR(dynamic[orderDate])=2023,9,IF(YEAR(dynamic[orderDate])=2024,10,NA))),FALSE) -> 17.665635 | M15: 27.2 | N15: =(dynamic[orderPrice]-dynamic[productCost])/dynamic[productCost] -> 0.53971256 | O15: 40 | P15: 0 | Q15: =dynamic[orderPrice]*dynamic[orderQuantity] -> 1088 | R15: =dynamic[orderTotal]*(1-dynamic[discountApllied]) -> 1088 | S15: =dynamic[revenue]-(dynamic[productCost]*dynamic[orderQuantity]) -> 381.3746 | T15: =IFERROR(dynamic[profit]/dynamic[revenue], 0) -> 0.35052813
A16: 10253 | B16: HANAR | C16: =VLOOKUP(dynamic[customerID],customers[],2,FALSE) -> Hanari Carnes | D16: 44752 | E16: =IFERROR(__xludf.DUMMYFUNCTION("COUNTUNIQUEIFS($A$2:$A16,$B$2:$B16,B16)"),2.0) -> 2 | F16: =IF(E16=1, 0, D16 - INDEX($D$2:$D16,MATCH(1, ($B$2:$B16=B16)*($E$2:$E16=E16-1), 0))) -> 2 | G16: =IF(MINIFS(dynamic[orderDate], dynamic[customerID], B16) >= DATE(2024,4,30)-120, "New", IF(MAXIFS(dynamic[orderCount], dynamic[customerID], B16)<=2, IF((DATE(2024,4,30) - MAXIFS(dynamic[orderDate], dynamic[customerID], B16)) > 180, "Non-Returning", "Dormant"), IF(AND(MAX(dynamic[sinceLastOrder]) > 365, (DATE(2024,4,30) - MAXIFS(dynamic[orderDate], dynamic[customerID], B16)) > 180), "Dormant", "Regular"))) -> Regular | H16: 31 | I16: =VLOOKUP(dynamic[productID],products[],2,FALSE) -> Gorgonzola Telino | J16: =VLOOKUP(dynamic[productID],products[],12,FALSE) -> Dairy Products | K16: =IF(VLOOKUP(dynamic[productID],products[],7,FALSE)=1,"Discontinued","Current") -> Current | L16: =VLOOKUP(dynamic[productID],products[],IF(YEAR(dynamic[orderDate])=2022,8,IF(YEAR(dynamic[orderDate])=2023,9,IF(YEAR(dynamic[orderDate])=2024,10,NA))),FALSE) -> 6.4403197 | M16: 10 | N16: =(dynamic[orderPrice]-dynamic[productCost])/dynamic[productCost] -> 0.55271794 | O16: 20 | P16: 0 | Q16: =dynamic[orderPrice]*dynamic[orderQuantity] -> 200 | R16: =dynamic[orderTotal]*(1-dynamic[discountApllied]) -> 200 | S16: =dynamic[revenue]-(dynamic[productCost]*dynamic[orderQuantity]) -> 71.193605 | T16: =IFERROR(dynamic[profit]/dynamic[revenue], 0) -> 0.35596803
A17: 10253 | B17: HANAR | C17: =VLOOKUP(dynamic[customerID],customers[],2,FALSE) -> Hanari Carnes | D17: 44752 | E17: =IFERROR(__xludf.DUMMYFUNCTION("COUNTUNIQUEIFS($A$2:$A17,$B$2:$B17,B17)"),2.0) -> 2 | F17: =IF(E17=1, 0, D17 - INDEX($D$2:$D17,MATCH(1, ($B$2:$B17=B17)*($E$2:$E17=E17-1), 0))) -> 2 | G17: =IF(MINIFS(dynamic[orderDate], dynamic[customerID], B17) >= DATE(2024,4,30)-120, "New", IF(MAXIFS(dynamic[orderCount], dynamic[customerID], B17)<=2, IF((DATE(2024,4,30) - MAXIFS(dynamic[orderDate], dynamic[customerID], B17)) > 180, "Non-Returning", "Dormant"), IF(AND(MAX(dynamic[sinceLastOrder]) > 365, (DATE(2024,4,30) - MAXIFS(dynamic[orderDate], dynamic[customerID], B17)) > 180), "Dormant", "Regular"))) -> Regular | H17: 39 | I17: =VLOOKUP(dynamic[productID],products[],2,FALSE) -> Chartreuse verte | J17: =VLOOKUP(dynamic[productID],products[],12,FALSE) -> Beverages | K17: =IF(VLOOKUP(dynamic[productID],products[],7,FALSE)=1,"Discontinued","Current") -> Current | L17: =VLOOKUP(dynamic[productID],products[],IF(YEAR(dynamic[orderDate])=2022,8,IF(YEAR(dynamic[orderDate])=2023,9,IF(YEAR(dynamic[orderDate])=2024,10,NA))),FALSE) -> 9.7435172 | M17: 14.4 | N17: =(dynamic[orderPrice]-dynamic[productCost])/dynamic[productCost] -> 0.47790574 | O17: 42 | P17: 0 | Q17: =dynamic[orderPrice]*dynamic[orderQuantity] -> 604.8 | R17: =dynamic[orderTotal]*(1-dynamic[discountApllied]) -> 604.8 | S17: =dynamic[revenue]-(dynamic[productCost]*dynamic[orderQuantity]) -> 195.57228 | T17: =IFERROR(dynamic[profit]/dynamic[revenue], 0) -> 0.32336686
A18: 10253 | B18: HANAR | C18: =VLOOKUP(dynamic[customerID],customers[],2,FALSE) -> Hanari Carnes | D18: 44752 | E18: =IFERROR(__xludf.DUMMYFUNCTION("COUNTUNIQUEIFS($A$2:$A18,$B$2:$B18,B18)"),2.0) -> 2 | F18: =IF(E18=1, 0, D18 - INDEX($D$2:$D18,MATCH(1, ($B$2:$B18=B18)*($E$2:$E18=E18-1), 0))) -> 2 | G18: =IF(MINIFS(dynamic[orderDate], dynamic[customerID], B18) >= DATE(2024,4,30)-120, "New", IF(MAXIFS(dynamic[orderCount], dynamic[customerID], B18)<=2, IF((DATE(2024,4,30) - MAXIFS(dynamic[orderDate], dynamic[customerID], B18)) > 180, "Non-Returning", "Dormant"), IF(AND(MAX(dynamic[sinceLastOrder]) > 365, (DATE(2024,4,30) - MAXIFS(dynamic[orderDate], dynamic[customerID], B18)) > 180), "Dormant", "Regular"))) -> Regular | H18: 49 | I18: =VLOOKUP(dynamic[productID],products[],2,FALSE) -> Maxilaku | J18: =VLOOKUP(dynamic[productID],products[],12,FALSE) -> Confections | K18: =IF(VLOOKUP(dynamic[productID],products[],7,FALSE)=1,"Discontinued","Current") -> Current | L18: =VLOOKUP(dynamic[productID],products[],IF(YEAR(dynamic[orderDate])=2022,8,IF(YEAR(dynamic[orderDate])=2023,9,IF(YEAR(dynamic[orderDate])=2024,10,NA))),FALSE) -> 12.566636 | M18: 16 | N18: =(dynamic[orderPrice]-dynamic[productCost])/dynamic[productCost] -> 0.27321268 | O18: 40 | P18: 0 | Q18: =dynamic[orderPrice]*dynamic[orderQuantity] -> 640 | R18: =dynamic[orderTotal]*(1-dynamic[discountApllied]) -> 640 | S18: =dynamic[revenue]-(dynamic[productCost]*dynamic[orderQuantity]) -> 137.33457 | T18: =IFERROR(dynamic[profit]/dynamic[revenue], 0) -> 0.21458526
A19: 10254 | B19: CHOPS | C19: =VLOOKUP(dynamic[customerID],customers[],2,FALSE) -> Chop-suey Chinese | D19: 44753 | E19: =IFERROR(__xludf.DUMMYFUNCTION("COUNTUNIQUEIFS($A$2:$A19,$B$2:$B19,B19)"),1.0) -> 1 | F19: =IF(E19=1, 0, D19 - INDEX($D$2:$D19,MATCH(1, ($B$2:$B19=B19)*($E$2:$E19=E19-1), 0))) -> 0 | G19: =IF(MINIFS(dynamic[orderDate], dynamic[customerID], B19) >= DATE(2024,4,30)-120, "New", IF(MAXIFS(dynamic[orderCount], dynamic[customerID], B19)<=2, IF((DATE(2024,4,30) - MAXIFS(dynamic[orderDate], dynamic[customerID], B19)) > 180, "Non-Returning", "Dormant"), IF(AND(MAX(dynamic[sinceLastOrder]) > 365, (DATE(2024,4,30) - MAXIFS(dynamic[orderDate], dynamic[customerID], B19)) > 180), "Dormant", "Regular"))) -> Regular | H19: 24 | I19: =VLOOKUP(dynamic[productID],products[],2,FALSE) -> Brigadeiros Maravilhosos da Lilian | J19: =VLOOKUP(dynamic[productID],products[],12,FALSE) -> Confections | K19: =IF(VLOOKUP(dynamic[productID],products[],7,FALSE)=1,"Discontinued","Current") -> Discontinued | L19: =VLOOKUP(dynamic[productID],products[],IF(YEAR(dynamic[orderDate])=2022,8,IF(YEAR(dynamic[orderDate])=2023,9,IF(YEAR(dynamic[orderDate])=2024,10,NA))),FALSE) -> 2.6811725 | M19: 3.6 | N19: =(dynamic[orderPrice]-dynamic[productCost])/dynamic[productCost] -> 0.34269617 | O19: 15 | P19: 0.15 | Q19: =dynamic[orderPrice]*dynamic[orderQuantity] -> 54 | R19: =dynamic[orderTotal]*(1-dynamic[discountApllied]) -> 45.9 | S19: =dynamic[revenue]-(dynamic[productCost]*dynamic[orderQuantity]) -> 5.6824131 | T19: =IFERROR(dynamic[profit]/dynamic[revenue], 0) -> 0.12379985
A20: 10254 | B20: CHOPS | C20: =VLOOKUP(dynamic[customerID],customers[],2,FALSE) -> Chop-suey Chinese | D20: 44753 | E20: =IFERROR(__xludf.DUMMYFUNCTION("COUNTUNIQUEIFS($A$2:$A20,$B$2:$B20,B20)"),1.0) -> 1 | F20: =IF(E20=1, 0, D20 - INDEX($D$2:$D20,MATCH(1, ($B$2:$B20=B20)*($E$2:$E20=E20-1), 0))) -> 0 | G20: =IF(MINIFS(dynamic[orderDate], dynamic[customerID], B20) >= DATE(2024,4,30)-120, "New", IF(MAXIFS(dynamic[orderCount], dynamic[customerID], B20)<=2, IF((DATE(2024,4,30) - MAXIFS(dynamic[orderDate], dynamic[customerID], B20)) > 180, "Non-Returning", "Dormant"), IF(AND(MAX(dynamic[sinceLastOrder]) > 365, (DATE(2024,4,30) - MAXIFS(dynamic[orderDate], dynamic[customerID], B20)) > 180), "Dormant", "Regular"))) -> Regular | H20: 55 | I20: =VLOOKUP(dynamic[productID],products[],2,FALSE) -> Pâté chinois | J20: =VLOOKUP(dynamic[productID],products[],12,FALSE) -> Meat/Poultry | K20: =IF(VLOOKUP(dynamic[productID],products[],7,FALSE)=1,"Discontinued","Current") -> Current | L20: =VLOOKUP(dynamic[productID],products[],IF(YEAR(dynamic[orderDate])=2022,8,IF(YEAR(dynamic[orderDate])=2023,9,IF(YEAR(dynamic[orderDate])=2024,10,NA))),FALSE) -> 12.974961 | M20: 19.2 | N20: =(dynamic[orderPrice]-dynamic[productCost])/dynamic[productCost] -> 0.47977329 | O20: 21 | P20: 0.15 | Q20: =dynamic[orderPrice]*dynamic[orderQuantity] -> 403.2 | R20: =dynamic[orderTotal]*(1-dynamic[discountApllied]) -> 342.72 | S20: =dynamic[revenue]-(dynamic[productCost]*dynamic[orderQuantity]) -> 70.245829 | T20: =IFERROR(dynamic[profit]/dynamic[revenue], 0) -> 0.20496565
A21: 10254 | B21: CHOPS | C21: =VLOOKUP(dynamic[customerID],customers[],2,FALSE) -> Chop-suey Chinese | D21: 44753 | E21: =IFERROR(__xludf.DUMMYFUNCTION("COUNTUNIQUEIFS($A$2:$A21,$B$2:$B21,B21)"),1.0) -> 1 | F21: =IF(E21=1, 0, D21 - INDEX($D$2:$D21,MATCH(1, ($B$2:$B21=B21)*($E$2:$E21=E21-1), 0))) -> 0 | G21: =IF(MINIFS(dynamic[orderDate], dynamic[customerID], B21) >= DATE(2024,4,30)-120, "New", IF(MAXIFS(dynamic[orderCount], dynamic[customerID], B21)<=2, IF((DATE(2024,4,30) - MAXIFS(dynamic[orderDate], dynamic[customerID], B21)) > 180, "Non-Returning", "Dormant"), IF(AND(MAX(dynamic[sinceLastOrder]) > 365, (DATE(2024,4,30) - MAXIFS(dynamic[orderDate], dynamic[customerID], B21)) > 180), "Dormant", "Regular"))) -> Regular | H21: 74 | I21: =VLOOKUP(dynamic[productID],products[],2,FALSE) -> Longlife Tofu | J21: =VLOOKUP(dynamic[productID],products[],12,FALSE) -> Produce | K21: =IF(VLOOKUP(dynamic[productID],products[],7,FALSE)=1,"Discontinued","Current") -> Current | L21: =VLOOKUP(dynamic[productID],products[],IF(YEAR(dynamic[orderDate])=2022,8,IF(YEAR(dynamic[orderDate])=2023,9,IF(YEAR(dynamic[orderDate])=2024,10,NA))),FALSE) -> 5.6671301 | M21: 8 | N21: =(dynamic[orderPrice]-dynamic[productCost])/dynamic[productCost] -> 0.41164925 | O21: 21 | P21: 0 | Q21: =dynamic[orderPrice]*dynamic[orderQuantity] -> 168 | R21: =dynamic[orderTotal]*(1-dynamic[discountApllied]) -> 168 | S21: =dynamic[revenue]-(dynamic[productCost]*dynamic[orderQuantity]) -> 48.990267 | T21: =IFERROR(dynamic[profit]/dynamic[revenue], 0) -> 0.29160873
A22: 10255 | B22: RICSU | C22: =VLOOKUP(dynamic[customerID],customers[],2,FALSE) -> Richter Supermarkt | D22: 44754 | E22: =IFERROR(__xludf.DUMMYFUNCTION("COUNTUNIQUEIFS($A$2:$A22,$B$2:$B22,B22)"),1.0) -> 1 | F22: =IF(E22=1, 0, D22 - INDEX($D$2:$D22,MATCH(1, ($B$2:$B22=B22)*($E$2:$E22=E22-1), 0))) -> 0 | G22: =IF(MINIFS(dynamic[orderDate], dynamic[customerID], B22) >= DATE(2024,4,30)-120, "New", IF(MAXIFS(dynamic[orderCount], dynamic[customerID], B22)<=2, IF((DATE(2024,4,30) - MAXIFS(dynamic[orderDate], dynamic[customerID], B22)) > 180, "Non-Returning", "Dormant"), IF(AND(MAX(dynamic[sinceLastOrder]) > 365, (DATE(2024,4,30) - MAXIFS(dynamic[orderDate], dynamic[customerID], B22)) > 180), "Dormant", "Regular"))) -> Regular | H22: 2 | I22: =VLOOKUP(dynamic[productID],products[],2,FALSE) -> Chang | J22: =VLOOKUP(dynamic[productID],products[],12,FALSE) -> Beverages | K22: =IF(VLOOKUP(dynamic[productID],products[],7,FALSE)=1,"Discontinued","Current") -> Current | L22: =VLOOKUP(dynamic[productID],products[],IF(YEAR(dynamic[orderDate])=2022,8,IF(YEAR(dynamic[orderDate])=2023,9,IF(YEAR(dynamic[orderDate])=2024,10,NA))),FALSE) -> 9.7687469 | M22: 15.2 | N22: =(dynamic[orderPrice]-dynamic[productCost])/dynamic[productCost] -> 0.55598258 | O22: 20 | P22: 0 | Q22: =dynamic[orderPrice]*dynamic[orderQuantity] -> 304 | R22: =dynamic[orderTotal]*(1-dynamic[discountApllied]) -> 304 | S22: =dynamic[revenue]-(dynamic[productCost]*dynamic[orderQuantity]) -> 108.62506 | T22: =IFERROR(dynamic[profit]/dynamic[revenue], 0) -> 0.35731928
A23: 10255 | B23: RICSU | C23: =VLOOKUP(dynamic[customerID],customers[],2,FALSE) -> Richter Supermarkt | D23: 44754 | E23: =IFERROR(__xludf.DUMMYFUNCTION("COUNTUNIQUEIFS($A$2:$A23,$B$2:$B23,B23)"),1.0) -> 1 | F23: =IF(E23=1, 0, D23 - INDEX($D$2:$D23,MATCH(1, ($B$2:$B23=B23)*($E$2:$E23=E23-1), 0))) -> 0 | G23: =IF(MINIFS(dynamic[orderDate], dynamic[customerID], B23) >= DATE(2024,4,30)-120, "New", IF(MAXIFS(dynamic[orderCount], dynamic[customerID], B23)<=2, IF((DATE(2024,4,30) - MAXIFS(dynamic[orderDate], dynamic[customerID], B23)) > 180, "Non-Returning", "Dormant"), IF(AND(MAX(dynamic[sinceLastOrder]) > 365, (DATE(2024,4,30) - MAXIFS(dynamic[orderDate], dynamic[customerID], B23)) > 180), "Dormant", "Regular"))) -> Regular | H23: 16 | I23: =VLOOKUP(dynamic[productID],products[],2,FALSE) -> Pavlova | J23: =VLOOKUP(dynamic[productID],products[],12,FALSE) -> Confections | K23: =IF(VLOOKUP(dynamic[productID],products[],7,FALSE)=1,"Discontinued","Current") -> Current | L23: =VLOOKUP(dynamic[productID],products[],IF(YEAR(dynamic[orderDate])=2022,8,IF(YEAR(dynamic[orderDate])=2023,9,IF(YEAR(dynamic[orderDate])=2024,10,NA))),FALSE) -> 9.8065801 | M23: 13.9 | N23: =(dynamic[orderPrice]-dynamic[productCost])/dynamic[productCost] -> 0.41741564 | O23: 35 | P23: 0 | Q23: =dynamic[orderPrice]*dynamic[orderQuantity] -> 486.5 | R23: =dynamic[orderTotal]*(1-dynamic[discountApllied]) -> 486.5 | S23: =dynamic[revenue]-(dynamic[productCost]*dynamic[orderQuantity]) -> 143.2697 | T23: =IFERROR(dynamic[profit]/dynamic[revenue], 0) -> 0.29449064
A24: 10255 | B24: RICSU | C24: =VLOOKUP(dynamic[customerID],customers[],2,FALSE) -> Richter Supermarkt | D24: 44754 | E24: =IFERROR(__xludf.DUMMYFUNCTION("COUNTUNIQUEIFS($A$2:$A24,$B$2:$B24,B24)"),1.0) -> 1 | F24: =IF(E24=1, 0, D24 - INDEX($D$2:$D24,MATCH(1, ($B$2:$B24=B24)*($E$2:$E24=E24-1), 0))) -> 0 | G24: =IF(MINIFS(dynamic[orderDate], dynamic[customerID], B24) >= DATE(2024,4,30)-120, "New", IF(MAXIFS(dynamic[orderCount], dynamic[customerID], B24)<=2, IF((DATE(2024,4,30) - MAXIFS(dynamic[orderDate], dynamic[customerID], B24)) > 180, "Non-Returning", "Dormant"), IF(AND(MAX(dynamic[sinceLastOrder]) > 365, (DATE(2024,4,30) - MAXIFS(dynamic[orderDate], dynamic[customerID], B24)) > 180), "Dormant", "Regular"))) -> Regular | H24: 36 | I24: =VLOOKUP(dynamic[productID],products[],2,FALSE) -> Inlagd Sill | J24: =VLOOKUP(dynamic[productID],products[],12,FALSE) -> Seafood | K24: =IF(VLOOKUP(dynamic[productID],products[],7,FALSE)=1,"Discontinued","Current") -> Current | L24: =VLOOKUP(dynamic[productID],products[],IF(YEAR(dynamic[orderDate])=2022,8,IF(YEAR(dynamic[orderDate])=2023,9,IF(YEAR(dynamic[orderDate])=2024,10,NA))),FALSE) -> 9.7682384 | M24: 15.2 | N24: =(dynamic[orderPrice]-dynamic[productCost])/dynamic[productCost] -> 0.55606357 | O24: 25 | P24: 0 | Q24: =dynamic[orderPrice]*dynamic[orderQuantity] -> 380 | R24: =dynamic[orderTotal]*(1-dynamic[discountApllied]) -> 380 | S24: =dynamic[revenue]-(dynamic[productCost]*dynamic[orderQuantity]) -> 135.79404 | T24: =IFERROR(dynamic[profit]/dynamic[revenue], 0) -> 0.35735273
A25: 10255 | B25: RICSU | C25: =VLOOKUP(dynamic[customerID],customers[],2,FALSE) -> Richter Supermarkt | D25: 44754 | E25: =IFERROR(__xludf.DUMMYFUNCTION("COUNTUNIQUEIFS($A$2:$A25,$B$2:$B25,B25)"),1.0) -> 1 | F25: =IF(E25=1, 0, D25 - INDEX($D$2:$D25,MATCH(1, ($B$2:$B25=B25)*($E$2:$E25=E25-1), 0))) -> 0 | G25: =IF(MINIFS(dynamic[orderDate], dynamic[customerID], B25) >= DATE(2024,4,30)-120, "New", IF(MAXIFS(dynamic[orderCount], dynamic[customerID], B25)<=2, IF((DATE(2024,4,30) - MAXIFS(dynamic[orderDate], dynamic[customerID], B25)) > 180, "Non-Returning", "Dormant"), IF(AND(MAX(dynamic[sinceLastOrder]) > 365, (DATE(2024,4,30) - MAXIFS(dynamic[orderDate], dynamic[customerID], B25)) > 180), "Dormant", "Regular"))) -> Regular | H25: 59 | I25: =VLOOKUP(dynamic[productID],products[],2,FALSE) -> Raclette Courdavault | J25: =VLOOKUP(dynamic[productID],products[],12,FALSE) -> Dairy Products | K25: =IF(VLOOKUP(dynamic[productID],products[],7,FALSE)=1,"Discontinued","Current") -> Current | L25: =VLOOKUP(dynamic[productID],products[],IF(YEAR(dynamic[orderDate])=2022,8,IF(YEAR(dynamic[orderDate])=2023,9,IF(YEAR(dynamic[orderDate])=2024,10,NA))),FALSE) -> 29.20352 | M25: 44 | N25: =(dynamic[orderPrice]-dynamic[productCost])/dynamic[productCost] -> 0.50666771 | O25: 30 | P25: 0 | Q25: =dynamic[orderPrice]*dynamic[orderQuantity] -> 1320 | R25: =dynamic[orderTotal]*(1-dynamic[discountApllied]) -> 1320 | S25: =dynamic[revenue]-(dynamic[productCost]*dynamic[orderQuantity]) -> 443.89441 | T25: =IFERROR(dynamic[profit]/dynamic[revenue], 0) -> 0.33628365
A26: 10256 | B26: WELLI | C26: =VLOOKUP(dynamic[customerID],customers[],2,FALSE) -> Wellington Importadora | D26: 44757 | E26: =IFERROR(__xludf.DUMMYFUNCTION("COUNTUNIQUEIFS($A$2:$A26,$B$2:$B26,B26)"),1.0) -> 1 | F26: =IF(E26=1, 0, D26 - INDEX($D$2:$D26,MATCH(1, ($B$2:$B26=B26)*($E$2:$E26=E26-1), 0))) -> 0 | G26: =IF(MINIFS(dynamic[orderDate], dynamic[customerID], B26) >= DATE(2024,4,30)-120, "New", IF(MAXIFS(dynamic[orderCount], dynamic[customerID], B26)<=2, IF((DATE(2024,4,30) - MAXIFS(dynamic[orderDate], dynamic[customerID], B26)) > 180, "Non-Returning", "Dormant"), IF(AND(MAX(dynamic[sinceLastOrder]) > 365, (DATE(2024,4,30) - MAXIFS(dynamic[orderDate], dynamic[customerID], B26)) > 180), "Dormant", "Regular"))) -> Regular | H26: 53 | I26: =VLOOKUP(dynamic[productID],products[],2,FALSE) -> Perth Pasties | J26: =VLOOKUP(dynamic[productID],products[],12,FALSE) -> Meat/Poultry | K26: =IF(VLOOKUP(dynamic[productID],products[],7,FALSE)=1,"Discontinued","Current") -> Discontinued | L26: =VLOOKUP(dynamic[productID],products[],IF(YEAR(dynamic[orderDate])=2022,8,IF(YEAR(dynamic[orderDate])=2023,9,IF(YEAR(dynamic[orderDate])=2024,10,NA))),FALSE) -> 18.33322 | M26: 26.2 | N26: =(dynamic[orderPrice]-dynamic[productCost])/dynamic[productCost] -> 0.42909974 | O26: 15 | P26: 0 | Q26: =dynamic[orderPrice]*dynamic[orderQuantity] -> 393 | R26: =dynamic[orderTotal]*(1-dynamic[discountApllied]) -> 393 | S26: =dynamic[revenue]-(dynamic[productCost]*dynamic[orderQuantity]) -> 118.0017 | T26: =IFERROR(dynamic[profit]/dynamic[revenue], 0) -> 0.30025878
A27: 10256 | B27: WELLI | C27: =VLOOKUP(dynamic[customerID],customers[],2,FALSE) -> Wellington Importadora | D27: 44757 | E27: =IFERROR(__xludf.DUMMYFUNCTION("COUNTUNIQUEIFS($A$2:$A27,$B$2:$B27,B27)"),1.0) -> 1 | F27: =IF(E27=1, 0, D27 - INDEX($D$2:$D27,MATCH(1, ($B$2:$B27=B27)*($E$2:$E27=E27-1), 0))) -> 0 | G27: =IF(MINIFS(dynamic[orderDate], dynamic[customerID], B27) >= DATE(2024,4,30)-120, "New", IF(MAXIFS(dynamic[orderCount], dynamic[customerID], B27)<=2, IF((DATE(2024,4,30) - MAXIFS(dynamic[orderDate], dynamic[customerID], B27)) > 180, "Non-Returning", "Dormant"), IF(AND(MAX(dynamic[sinceLastOrder]) > 365, (DATE(2024,4,30) - MAXIFS(dynamic[orderDate], dynamic[customerID], B27)) > 180), "Dormant", "Regular"))) -> Regular | H27: 77 | I27: =VLOOKUP(dynamic[productID],products[],2,FALSE) -> Original Frankfurter grüne Soße | J27: =VLOOKUP(dynamic[productID],products[],12,FALSE) -> Condiments | K27: =IF(VLOOKUP(dynamic[productID],products[],7,FALSE)=1,"Discontinued","Current") -> Current | L27: =VLOOKUP(dynamic[productID],products[],IF(YEAR(dynamic[orderDate])=2022,8,IF(YEAR(dynamic[orderDate])=2023,9,IF(YEAR(dynamic[orderDate])=2024,10,NA))),FALSE) -> 7.4302728 | M27: 10.4 | N27: =(dynamic[orderPrice]-dynamic[productCost])/dynamic[productCost] -> 0.39967942 | O27: 12 | P27: 0 | Q27: =dynamic[orderPrice]*dynamic[orderQuantity] -> 124.8 | R27: =dynamic[orderTotal]*(1-dynamic[discountApllied]) -> 124.8 | S27: =dynamic[revenue]-(dynamic[productCost]*dynamic[orderQuantity]) -> 35.636726 | T27: =IFERROR(dynamic[profit]/dynamic[revenue], 0) -> 0.28555069
